<?xml version="1.0" encoding="utf-8"?>
<mujoco model="qube">
    <compiler angle="radian" meshdir="../meshes/" />
    <size njmax="500" nconmax="100" />
    <asset>
        <texture type="skybox" builtin="gradient" rgb1="0.44 0.85 0.56" rgb2="0.46 0.87 0.58" width="32" height="192" />
        <texture type="2d" name="texbody" builtin="flat" rgb1="0 0 0" width="1024" height="1024" />
        <texture type="2d" name="texfloor" builtin="flat" rgb1="1 1 1" width="1024" height="1024" />
        <texture type="2d" name="texred" builtin="flat" rgb1="0.698 0.1333 0.1333" width="1024" height="1024" />
        <texture type="2d" name="texsilver" builtin="flat" rgb1="0.7529 0.7529 0.7529" width="512" height="512" />
        <material name="bodyMat" texture="texbody" specular="0.75" shininess="0.1" />
        <material name="floorMat" texture="texfloor" specular="0.75" shininess="0.3" />
        <material name="redMat" texture="texred" specular="1" shininess="0.9" />
        <material name="silverMat" texture="texsilver" specular="0.75" shininess="0.3" />
        <mesh name="qube0:base" file="../meshes/qube_block.stl" />
        <mesh name="qube0:motor" file="../meshes/qube_motor_with_cable.stl" />
        <mesh name="qube0:arm" file="../meshes/qube_arm_ml.stl" />
        <mesh name="qube0:pole" file="../meshes/qube_pole_ml.stl" />
    </asset>
    <worldbody>
        <geom name="ground" size="5 5 1" type="plane" contype="0" conaffinity="0" material="floorMat" />
        <camera name="view" pos="-5 -5 15" quat="0.663439 0.567899 0.316804 -0.370101" />
        <light pos="0.051036 -0.0321818 0.5" dir="0 0 -1" diffuse="0.8 0.8 0.8" specular="0.9 0.9 0.9" />
        <body name="body" pos="0 0 0">
            <inertial pos="-0.000123329 0.00106812 0.0550479" quat="0.992378 0.0866092 0.00277942 -0.0876238" mass="1.1" diaginertia="0.00195952 0.00195133 0.0016488" />
            <geom name="qube0:base" type="mesh" contype="0" conaffinity="0" condim="1" friction="0 0 0" material="bodyMat" mesh="qube0:base" />
            <body name="motor" pos="0 0 0.12672">
                <inertial pos="-5.45435e-05 -0.00568089 0.00569803" quat="0.673228 0.739431 -0.00224326 0.000917125" mass="0.0512548" diaginertia="2.26942e-05 1.37989e-05 1.20931e-05" />
                <joint name="base_motor" pos="0 0 0" axis="0 0 1" range="-90 90" />
                <geom name="qube0:motor" type="mesh" material="redMat" mesh="qube0:motor" />
                <body name="arm" pos="0 -0.054882 0">
                    <inertial pos="8.77776e-09 4.03949e-08 -1.49835e-07" quat="0.5 0.5 -0.5 0.5" mass="0.095" diaginertia="3.93678e-05 3.93678e-05 4.79711e-07" />
                    <joint name="arm_pole" pos="0 0 0" axis="0 1 0" range="-90 90" />
                    <geom name="qube0:arm" type="mesh" material="silverMat" mesh="qube0:arm" />
                    <body name="pole" pos="0 -0.030562 0">
                        <inertial pos="2.23818e-05 -3.94236e-08 0.0496698" mass="0.024" diaginertia="3.42313e-05 3.42252e-05 2.52484e-07" />
                        <geom name="qube0:pole" type="mesh" material="redMat" mesh="qube0:pole" />
                    </body>
                </body>
            </body>
        </body>
        <body name="B0" pos="0 -0.02672 0.14399" quat="-0.707107 0 0.707107 0">
            <inertial pos="0 0 0" quat="0.707107 0 0.707107 0" mass="0.00012242" diaginertia="1.52526e-09 1.52526e-09 2.01862e-10" />
            <geom name="G0" size="0.001816 0.005" quat="0.707107 0 0.707107 0" type="capsule" material="bodyMat" />
            <body name="B1" pos="0.01 0 0">
                <inertial pos="0 0 0" quat="0.707107 0 0.707107 0" mass="0.00012242" diaginertia="1.52526e-09 1.52526e-09 2.01862e-10" />
                <joint name="J0_1" pos="-0.005 0 0" axis="0 1 0" group="3" />
                <joint name="J1_1" pos="-0.005 0 0" axis="0 0 1" group="3" />
                <joint name="JT1" pos="-0.005 0 0" axis="1 0 0" group="3" stiffness="0.0001" />
                <geom name="G1" size="0.001816 0.005" quat="0.707107 0 0.707107 0" type="capsule" material="bodyMat" />
                <body name="B2" pos="0.01 0 0">
                    <inertial pos="0 0 0" quat="0.707107 0 0.707107 0" mass="0.00012242" diaginertia="1.52526e-09 1.52526e-09 2.01862e-10" />
                    <joint name="J0_2" pos="-0.005 0 0" axis="0 1 0" group="3" />
                    <joint name="J1_2" pos="-0.005 0 0" axis="0 0 1" group="3" />
                    <joint name="JT2" pos="-0.005 0 0" axis="1 0 0" group="3" stiffness="0.0001" />
                    <geom name="G2" size="0.001816 0.005" quat="0.707107 0 0.707107 0" type="capsule" material="bodyMat" />
                    <body name="B3" pos="0.01 0 0">
                        <inertial pos="0 0 0" quat="0.707107 0 0.707107 0" mass="0.00012242" diaginertia="1.52526e-09 1.52526e-09 2.01862e-10" />
                        <joint name="J0_3" pos="-0.005 0 0" axis="0 1 0" group="3" />
                        <joint name="J1_3" pos="-0.005 0 0" axis="0 0 1" group="3" />
                        <joint name="JT3" pos="-0.005 0 0" axis="1 0 0" group="3" stiffness="0.0001" />
                        <geom name="G3" size="0.001816 0.005" quat="0.707107 0 0.707107 0" type="capsule" material="bodyMat" />
                        <body name="B4" pos="0.01 0 0">
                            <inertial pos="0 0 0" quat="0.707107 0 0.707107 0" mass="0.00012242" diaginertia="1.52526e-09 1.52526e-09 2.01862e-10" />
                            <joint name="J0_4" pos="-0.005 0 0" axis="0 1 0" group="3" />
                            <joint name="J1_4" pos="-0.005 0 0" axis="0 0 1" group="3" />
                            <joint name="JT4" pos="-0.005 0 0" axis="1 0 0" group="3" stiffness="0.0001" />
                            <geom name="G4" size="0.001816 0.005" quat="0.707107 0 0.707107 0" type="capsule" material="bodyMat" />
                            <body name="B5" pos="0.01 0 0">
                                <inertial pos="0 0 0" quat="0.707107 0 0.707107 0" mass="0.00012242" diaginertia="1.52526e-09 1.52526e-09 2.01862e-10" />
                                <joint name="J0_5" pos="-0.005 0 0" axis="0 1 0" group="3" />
                                <joint name="J1_5" pos="-0.005 0 0" axis="0 0 1" group="3" />
                                <joint name="JT5" pos="-0.005 0 0" axis="1 0 0" group="3" stiffness="0.0001" />
                                <geom name="G5" size="0.001816 0.005" quat="0.707107 0 0.707107 0" type="capsule" material="bodyMat" />
                                <body name="B6" pos="0.01 0 0">
                                    <inertial pos="0 0 0" quat="0.707107 0 0.707107 0" mass="0.00012242" diaginertia="1.52526e-09 1.52526e-09 2.01862e-10" />
                                    <joint name="J0_6" pos="-0.005 0 0" axis="0 1 0" group="3" />
                                    <joint name="J1_6" pos="-0.005 0 0" axis="0 0 1" group="3" />
                                    <joint name="JT6" pos="-0.005 0 0" axis="1 0 0" group="3" stiffness="0.0001" />
                                    <geom name="G6" size="0.001816 0.005" quat="0.707107 0 0.707107 0" type="capsule" material="bodyMat" />
                                    <body name="B7" pos="0.01 0 0">
                                        <inertial pos="0 0 0" quat="0.707107 0 0.707107 0" mass="0.00012242" diaginertia="1.52526e-09 1.52526e-09 2.01862e-10" />
                                        <joint name="J0_7" pos="-0.005 0 0" axis="0 1 0" group="3" />
                                        <joint name="J1_7" pos="-0.005 0 0" axis="0 0 1" group="3" />
                                        <joint name="JT7" pos="-0.005 0 0" axis="1 0 0" group="3" stiffness="0.0001" />
                                        <geom name="G7" size="0.001816 0.005" quat="0.707107 0 0.707107 0" type="capsule" material="bodyMat" />
                                        <body name="B8" pos="0.01 0 0">
                                            <inertial pos="0 0 0" quat="0.707107 0 0.707107 0" mass="0.00012242" diaginertia="1.52526e-09 1.52526e-09 2.01862e-10" />
                                            <joint name="J0_8" pos="-0.005 0 0" axis="0 1 0" group="3" />
                                            <joint name="J1_8" pos="-0.005 0 0" axis="0 0 1" group="3" />
                                            <joint name="JT8" pos="-0.005 0 0" axis="1 0 0" group="3" stiffness="0.0001" />
                                            <geom name="G8" size="0.001816 0.005" quat="0.707107 0 0.707107 0" type="capsule" material="bodyMat" />
                                            <body name="B9" pos="0.01 0 0">
                                                <inertial pos="0 0 0" quat="0.707107 0 0.707107 0" mass="0.00012242" diaginertia="1.52526e-09 1.52526e-09 2.01862e-10" />
                                                <joint name="J0_9" pos="-0.005 0 0" axis="0 1 0" group="3" />
                                                <joint name="J1_9" pos="-0.005 0 0" axis="0 0 1" group="3" />
                                                <joint name="JT9" pos="-0.005 0 0" axis="1 0 0" group="3" stiffness="0.0001" />
                                                <geom name="G9" size="0.001816 0.005" quat="0.707107 0 0.707107 0" type="capsule" material="bodyMat" />
                                                <body name="B10" pos="0.01 0 0">
                                                    <inertial pos="0 0 0" quat="0.707107 0 0.707107 0" mass="0.00012242" diaginertia="1.52526e-09 1.52526e-09 2.01862e-10" />
                                                    <joint name="J0_10" pos="-0.005 0 0" axis="0 1 0" group="3" />
                                                    <joint name="J1_10" pos="-0.005 0 0" axis="0 0 1" group="3" />
                                                    <joint name="JT10" pos="-0.005 0 0" axis="1 0 0" group="3" stiffness="0.0001" />
                                                    <geom name="G10" size="0.001816 0.005" quat="0.707107 0 0.707107 0" type="capsule" material="bodyMat" />
                                                    <body name="B11" pos="0.01 0 0">
                                                        <inertial pos="0 0 0" quat="0.707107 0 0.707107 0" mass="0.00012242" diaginertia="1.52526e-09 1.52526e-09 2.01862e-10" />
                                                        <joint name="J0_11" pos="-0.005 0 0" axis="0 1 0" group="3" />
                                                        <joint name="J1_11" pos="-0.005 0 0" axis="0 0 1" group="3" />
                                                        <joint name="JT11" pos="-0.005 0 0" axis="1 0 0" group="3" stiffness="0.0001" />
                                                        <geom name="G11" size="0.001816 0.005" quat="0.707107 0 0.707107 0" type="capsule" material="bodyMat" />
                                                        <body name="B12" pos="0.01 0 0">
                                                            <inertial pos="0 0 0" quat="0.707107 0 0.707107 0" mass="0.00012242" diaginertia="1.52526e-09 1.52526e-09 2.01862e-10" />
                                                            <joint name="J0_12" pos="-0.005 0 0" axis="0 1 0" group="3" />
                                                            <joint name="J1_12" pos="-0.005 0 0" axis="0 0 1" group="3" />
                                                            <joint name="JT12" pos="-0.005 0 0" axis="1 0 0" group="3" stiffness="0.0001" />
                                                            <geom name="G12" size="0.001816 0.005" quat="0.707107 0 0.707107 0" type="capsule" material="bodyMat" />
                                                            <body name="B13" pos="0.01 0 0">
                                                                <inertial pos="0 0 0" quat="0.707107 0 0.707107 0" mass="0.00012242" diaginertia="1.52526e-09 1.52526e-09 2.01862e-10" />
                                                                <joint name="J0_13" pos="-0.005 0 0" axis="0 1 0" group="3" />
                                                                <joint name="J1_13" pos="-0.005 0 0" axis="0 0 1" group="3" />
                                                                <joint name="JT13" pos="-0.005 0 0" axis="1 0 0" group="3" stiffness="0.0001" />
                                                                <geom name="G13" size="0.001816 0.005" quat="0.707107 0 0.707107 0" type="capsule" material="bodyMat" />
                                                                <body name="B14" pos="0.01 0 0">
                                                                    <inertial pos="0 0 0" quat="0.707107 0 0.707107 0" mass="0.00012242" diaginertia="1.52526e-09 1.52526e-09 2.01862e-10" />
                                                                    <joint name="J0_14" pos="-0.005 0 0" axis="0 1 0" group="3" />
                                                                    <joint name="J1_14" pos="-0.005 0 0" axis="0 0 1" group="3" />
                                                                    <joint name="JT14" pos="-0.005 0 0" axis="1 0 0" group="3" stiffness="0.0001" />
                                                                    <geom name="G14" size="0.001816 0.005" quat="0.707107 0 0.707107 0" type="capsule" material="bodyMat" />
                                                                    <body name="B15" pos="0.01 0 0">
                                                                        <inertial pos="0 0 0" quat="0.707107 0 0.707107 0" mass="0.00012242" diaginertia="1.52526e-09 1.52526e-09 2.01862e-10" />
                                                                        <joint name="J0_15" pos="-0.005 0 0" axis="0 1 0" group="3" />
                                                                        <joint name="J1_15" pos="-0.005 0 0" axis="0 0 1" group="3" />
                                                                        <joint name="JT15" pos="-0.005 0 0" axis="1 0 0" group="3" stiffness="0.0001" />
                                                                        <geom name="G15" size="0.001816 0.005" quat="0.707107 0 0.707107 0" type="capsule" material="bodyMat" />
                                                                        <body name="B16" pos="0.01 0 0">
                                                                            <inertial pos="0 0 0" quat="0.707107 0 0.707107 0" mass="0.00012242" diaginertia="1.52526e-09 1.52526e-09 2.01862e-10" />
                                                                            <joint name="J0_16" pos="-0.005 0 0" axis="0 1 0" group="3" />
                                                                            <joint name="J1_16" pos="-0.005 0 0" axis="0 0 1" group="3" />
                                                                            <joint name="JT16" pos="-0.005 0 0" axis="1 0 0" group="3" stiffness="0.0001" />
                                                                            <geom name="G16" size="0.001816 0.005" quat="0.707107 0 0.707107 0" type="capsule" material="bodyMat" />
                                                                            <body name="B17" pos="0.01 0 0">
                                                                                <inertial pos="0 0 0" quat="0.707107 0 0.707107 0" mass="0.00012242" diaginertia="1.52526e-09 1.52526e-09 2.01862e-10" />
                                                                                <joint name="J0_17" pos="-0.005 0 0" axis="0 1 0" group="3" />
                                                                                <joint name="J1_17" pos="-0.005 0 0" axis="0 0 1" group="3" />
                                                                                <joint name="JT17" pos="-0.005 0 0" axis="1 0 0" group="3" stiffness="0.0001" />
                                                                                <geom name="G17" size="0.001816 0.005" quat="0.707107 0 0.707107 0" type="capsule" material="bodyMat" />
                                                                                <body name="B18" pos="0.01 0 0">
                                                                                    <inertial pos="0 0 0" quat="0.707107 0 0.707107 0" mass="0.00012242" diaginertia="1.52526e-09 1.52526e-09 2.01862e-10" />
                                                                                    <joint name="J0_18" pos="-0.005 0 0" axis="0 1 0" group="3" />
                                                                                    <joint name="J1_18" pos="-0.005 0 0" axis="0 0 1" group="3" />
                                                                                    <joint name="JT18" pos="-0.005 0 0" axis="1 0 0" group="3" stiffness="0.0001" />
                                                                                    <geom name="G18" size="0.001816 0.005" quat="0.707107 0 0.707107 0" type="capsule" material="bodyMat" />
                                                                                    <body name="B19" pos="0.01 0 0">
                                                                                        <inertial pos="0 0 0" quat="0.707107 0 0.707107 0" mass="0.00012242" diaginertia="1.52526e-09 1.52526e-09 2.01862e-10" />
                                                                                        <joint name="J0_19" pos="-0.005 0 0" axis="0 1 0" group="3" />
                                                                                        <joint name="J1_19" pos="-0.005 0 0" axis="0 0 1" group="3" />
                                                                                        <joint name="JT19" pos="-0.005 0 0" axis="1 0 0" group="3" stiffness="0.0001" />
                                                                                        <geom name="G19" size="0.001816 0.005" quat="0.707107 0 0.707107 0" type="capsule" material="bodyMat" />
                                                                                        <body name="B20" pos="0.01 0 0">
                                                                                            <inertial pos="0 0 0" quat="0.707107 0 0.707107 0" mass="0.00012242" diaginertia="1.52526e-09 1.52526e-09 2.01862e-10" />
                                                                                            <joint name="J0_20" pos="-0.005 0 0" axis="0 1 0" group="3" />
                                                                                            <joint name="J1_20" pos="-0.005 0 0" axis="0 0 1" group="3" />
                                                                                            <joint name="JT20" pos="-0.005 0 0" axis="1 0 0" group="3" stiffness="0.0001" />
                                                                                            <geom name="G20" size="0.001816 0.005" quat="0.707107 0 0.707107 0" type="capsule" material="bodyMat" />
                                                                                        </body>
                                                                                    </body>
                                                                                </body>
                                                                            </body>
                                                                        </body>
                                                                    </body>
                                                                </body>
                                                            </body>
                                                        </body>
                                                    </body>
                                                </body>
                                            </body>
                                        </body>
                                    </body>
                                </body>
                            </body>
                        </body>
                    </body>
                </body>
            </body>
        </body>
    </worldbody>
    <equality>
        <joint joint1="JT1" polycoef="0 1 0 0 0" />
        <joint joint1="JT2" polycoef="0 1 0 0 0" />
        <joint joint1="JT3" polycoef="0 1 0 0 0" />
        <joint joint1="JT4" polycoef="0 1 0 0 0" />
        <joint joint1="JT5" polycoef="0 1 0 0 0" />
        <joint joint1="JT6" polycoef="0 1 0 0 0" />
        <joint joint1="JT7" polycoef="0 1 0 0 0" />
        <joint joint1="JT8" polycoef="0 1 0 0 0" />
        <joint joint1="JT9" polycoef="0 1 0 0 0" />
        <joint joint1="JT10" polycoef="0 1 0 0 0" />
        <joint joint1="JT11" polycoef="0 1 0 0 0" />
        <joint joint1="JT12" polycoef="0 1 0 0 0" />
        <joint joint1="JT13" polycoef="0 1 0 0 0" />
        <joint joint1="JT14" polycoef="0 1 0 0 0" />
        <joint joint1="JT15" polycoef="0 1 0 0 0" />
        <joint joint1="JT16" polycoef="0 1 0 0 0" />
        <joint joint1="JT17" polycoef="0 1 0 0 0" />
        <joint joint1="JT18" polycoef="0 1 0 0 0" />
        <joint joint1="JT19" polycoef="0 1 0 0 0" />
        <joint joint1="JT20" polycoef="0 1 0 0 0" />
        <connect name="motor_cable" body1="motor" body2="B0" anchor="0 -0.02672 0.01727" />
        <connect name="base_cable" body1="body" body2="B10" anchor="0 0.026741 0.10546" />
    </equality>
    <actuator>
        <general name="motor_rotation" joint="base_motor" ctrllimited="true" ctrlrange="-18 18" biastype="affine" gainprm="0.0025 0 0 0 0 0 0 0 0 0" biasprm="0 0 -0.0025 0 0 0 0 0 0 0" />
    </actuator>
</mujoco>