<?xml version="1.0" encoding="utf-8"?>
<mujoco model="qube">
    <compiler angle="radian" coordinate="local" meshdir="../meshes/" inertiafromgeom="auto"/>
    <option gravity="0 0 -9.81" integrator="Euler"/>

    <!-- Materials & Assets -->
    <asset>
        <!-- Assets -->
        <include file="shared_assets.xml"/>

        <!-- Textures -->
        <texture type="2d" name="texbody" builtin="flat" rgb1="0 0 0" width="1024" height="1024" />
        <texture type="2d" name="texfloor" builtin="flat" rgb1="1 1 1" width="1024" height="1024" />
        <texture type="2d" name="texred" builtin="flat" rgb1="0.721569 0.25098 0.235294" width="1024" height="1024" />
        <texture type="2d" name="texsilver" builtin="flat" rgb1="0.7529 0.7529 0.7529" width="512" height="512" />

        <!-- Materials -->
        <material name="floorMat" texture="texfloor" specular="1.0" shininess="0.1" />
        <material name="bodyMat" texture="texbody" specular="0.75" shininess="0.3" />
        <material name="redMat" texture="texred" specular="1.0" shininess="0.9" reflectance="1.0"/>
        <material name="silverMat" texture="texsilver" specular="0.75" shininess="0.6" reflectance="1.0"/>
    </asset>

    <visual>
        <global fovy="45" />
    </visual>

    <worldbody>
        <light diffuse=".8 .8 .8" dir="0 0 -1" directional="false" pos="0.051036 -0.032181818 0.5" specular="0.9 0.9 0.9" castshadow="true"/>

        <camera pos="-5 -5 15" name="view" euler="-30 0 -45"/>

        <geom conaffinity="0" contype="0" name="ground" pos="0 0 0" size="5 5 1" type="plane" material="floorMat"/>

        <!-- <body name="cube" pos="0 -0.026 0.15">
            <geom name="cube:base" pos="0 0 0" type="mesh" contype="0" conaffinity="0" condim="1" friction="0 0 0" material="bodyMat" mesh="cube" />
        </body> -->

        <!-- Qube -->
        <body name="base" pos="0 0 0" quat="0 0 0 1">
            <inertial pos="0.000323 -0.00132 0.054992" mass="1.0" fullinertia="0.16666666667 0.16666666667 0.16666666667 0.000000000 0.000000000 0.000000000" />
            <geom name="qube0:base" pos="0.000323 -0.00132 0.054992" type="mesh" contype="0" conaffinity="0" condim="1" friction="0 0 0" material="bodyMat" mesh="qube0:base" />
            <geom name="qube0:base:screw:01" pos="0.009938 0.009932 0.10653" type="mesh" contype="0" conaffinity="0" condim="1" friction="0 0 0" material="silverMat" mesh="qube0:base:screw:01" />
            <geom name="qube0:base:screw:02" pos="0.009938 -0.009927 0.10653" type="mesh" contype="0" conaffinity="0" condim="1" friction="0 0 0" material="silverMat" mesh="qube0:base:screw:02" />
            <geom name="qube0:base:screw:03" pos="-0.009938 0.009932 0.10653" type="mesh" contype="0" conaffinity="0" condim="1" friction="0 0 0" material="silverMat" mesh="qube0:base:screw:03" />
            <geom name="qube0:base:screw:04" pos="-0.009938 -0.009931 0.10653" type="mesh" contype="0" conaffinity="0" condim="1" friction="0 0 0" material="silverMat" mesh="qube0:base:screw:04" />
            <geom name="qube0:base:aux:female" pos="0 -0.026394 0.1078" type="mesh" contype="0" conaffinity="0" condim="1" friction="0 0 0" material="silverMat" mesh="qube0:base:aux:female" />


            <body name="motor" pos="0 0 0.12672">
				<body name="cable" pos="0.000031 0.025329 0.00124">
					<!-- <geom name="qube:cable" type="mesh" contype="0" conaffinity="0" condim="1" friction="0 0 0" material="bodyMat" mesh="qube0:cable" /> -->
					<geom name="qube:cable:aux:male" pos="0 -0.05155 -0.005" type="mesh" contype="0" conaffinity="0" condim="1" friction="0 0 0" material="bodyMat" mesh="qube0:cable:aux:male" />
		<body name="B0" pos="0 0 0.02" quat="0 -0.7071067 0 -0.7071069">
			<inertial pos="0 0 0" quat="0.707107 0 0.707107 0" mass="0.000625" diaginertia="9.41594e-10 9.41594e-10 9.14498e-11" />
			<geom name="G0" size="0.0015 0.005" quat="0.707107 0 0.707107 0" type="capsule" />
			<body name="B1" pos="0.01 0 0">
				<joint name="JT1" type="hinge" pos="-0.005 0 0" axis="0 0 1" group="3" damping="1" stiffness="0" limited="true" range="0 0.0872664626" />
				<joint name="JT1_2" type="hinge" pos="-0.005 0 0" axis="0 1 0" group="3" damping="1" stiffness="0" limited="true" range="0 0.0872664626" />
				<joint name="JT1_3" type="hinge" pos="-0.005 0 0" axis="1 0 0" group="3" damping="1" stiffness="0" limited="true" range="0 0.0872664626" />
				<inertial pos="0 0 0" quat="0.707107 0 0.707107 0" mass="0.000625" diaginertia="9.41594e-10 9.41594e-10 9.14498e-11" />
				<geom name="G1" size="0.0015 0.005" quat="0.707107 0 0.707107 0" type="capsule" />
				<body name="B2" pos="0.01 0 0">
					<joint name="JT2" type="hinge" pos="-0.005 0 0" axis="0 0 1" group="3" damping="1" stiffness="0" limited="true" range="0 0.0872664626" />
					<joint name="JT2_2" type="hinge" pos="-0.005 0 0" axis="0 1 0" group="3" damping="1" stiffness="0" limited="true" range="0 0.0872664626" />
					<joint name="JT2_3" type="hinge" pos="-0.005 0 0" axis="1 0 0" group="3" damping="1" stiffness="0" limited="true" range="0 0.0872664626" />
					<inertial pos="0 0 0" quat="0.707107 0 0.707107 0" mass="0.000625" diaginertia="9.41594e-10 9.41594e-10 9.14498e-11" />
					<geom name="G2" size="0.0015 0.005" quat="0.707107 0 0.707107 0" type="capsule" />
					<body name="B3" pos="0.01 0 0">
						<joint name="JT3" type="hinge" pos="-0.005 0 0" axis="0 0 1" group="3" damping="1" stiffness="0" limited="true" range="0 0.0872664626" />
						<joint name="JT3_2" type="hinge" pos="-0.005 0 0" axis="0 1 0" group="3" damping="1" stiffness="0" limited="true" range="0 0.0872664626" />
						<joint name="JT3_3" type="hinge" pos="-0.005 0 0" axis="1 0 0" group="3" damping="1" stiffness="0" limited="true" range="0 0.0872664626" />
						<inertial pos="0 0 0" quat="0.707107 0 0.707107 0" mass="0.000625" diaginertia="9.41594e-10 9.41594e-10 9.14498e-11" />
						<geom name="G3" size="0.0015 0.005" quat="0.707107 0 0.707107 0" type="capsule" />
						<body name="B4" pos="0.009807852804032305 0.0019509032201612826 0.0">
							<joint name="JT4" type="hinge" pos="-0.004619397662556434 -0.001913417161825449 0.0" axis="0 0 1" group="3" damping="1" stiffness="0" limited="true" range="0 0.0872664626" />
							<joint name="JT4_2" type="hinge" pos="-0.004619397662556434 -0.001913417161825449 0.0" axis="0 1 0" group="3" damping="1" stiffness="0" limited="true" range="0 0.0872664626" />
							<joint name="JT4_3" type="hinge" pos="-0.004619397662556434 -0.001913417161825449 0.0" axis="1 0 0" group="3" damping="1" stiffness="0" limited="true" range="0 0.0872664626" />
							<inertial pos="0 0 0" quat="0.6935201372700871 -0.1379497323298584 0.6935201372700871 0.1379497323298584" mass="0.000625" diaginertia="9.41594e-10 9.41594e-10 9.14498e-11" />
							<geom name="G4" size="0.0015 0.005" quat="0.6935201372700871 -0.1379497323298584 0.6935201372700871 0.1379497323298584" type="capsule" />
							<body name="B5" pos="0.008314696123025453 0.005555702330196022 0.0">
								<joint name="JT5" type="hinge" pos="-0.003535533905932738 -0.0035355339059327372 0.0" axis="0 0 1" group="3" damping="1" stiffness="0" limited="true" range="0 0.0872664626" />
								<joint name="JT5_2" type="hinge" pos="-0.003535533905932738 -0.0035355339059327372 0.0" axis="0 1 0" group="3" damping="1" stiffness="0" limited="true" range="0 0.0872664626" />
								<joint name="JT5_3" type="hinge" pos="-0.003535533905932738 -0.0035355339059327372 0.0" axis="1 0 0" group="3" damping="1" stiffness="0" limited="true" range="0 0.0872664626" />
								<inertial pos="0 0 0" quat="0.6532816845954584 -0.2705981338093816 0.6532816845954584 0.2705981338093816" mass="0.000625" diaginertia="9.41594e-10 9.41594e-10 9.14498e-11" />
								<geom name="G5" size="0.0015 0.005" quat="0.6532816845954584 -0.2705981338093816 0.6532816845954584 0.2705981338093816" type="capsule" />
								<body name="B6" pos="0.005555702330196023 0.00831469612302545 0.0">
									<joint name="JT6" type="hinge" pos="-0.0019134171618254492 -0.004619397662556434 0.0" axis="0 0 1" group="3" damping="1" stiffness="0" limited="true" range="0 0.0872664626" />
									<joint name="JT6_2" type="hinge" pos="-0.0019134171618254492 -0.004619397662556434 0.0" axis="0 1 0" group="3" damping="1" stiffness="0" limited="true" range="0 0.0872664626" />
									<joint name="JT6_3" type="hinge" pos="-0.0019134171618254492 -0.004619397662556434 0.0" axis="1 0 0" group="3" damping="1" stiffness="0" limited="true" range="0 0.0872664626" />
									<inertial pos="0 0 0" quat="0.5879379831464159 -0.39284760075979186 0.5879379831464159 0.39284760075979186" mass="0.000625" diaginertia="9.41594e-10 9.41594e-10 9.14498e-11" />
									<geom name="G6" size="0.0015 0.005" quat="0.5879379831464159 -0.39284760075979186 0.5879379831464159 0.39284760075979186" type="capsule" />
									<body name="B7" pos="0.001950903220161283 0.009807852804032305 0.0">
										<joint name="JT7" type="hinge" pos="-3.061616997868383e-19 -0.005 0.0" axis="0 0 1" group="3" damping="1" stiffness="0" limited="true" range="0 0.0872664626" />
										<joint name="JT7_2" type="hinge" pos="-3.061616997868383e-19 -0.005 0.0" axis="0 1 0" group="3" damping="1" stiffness="0" limited="true" range="0 0.0872664626" />
										<joint name="JT7_3" type="hinge" pos="-3.061616997868383e-19 -0.005 0.0" axis="1 0 0" group="3" damping="1" stiffness="0" limited="true" range="0 0.0872664626" />
										<inertial pos="0 0 0" quat="0.5000001547244761 -0.500000154724476 0.5000001547244761 0.500000154724476" mass="0.000625" diaginertia="9.41594e-10 9.41594e-10 9.14498e-11" />
										<geom name="G7" size="0.0015 0.005" quat="0.5000001547244761 -0.500000154724476 0.5000001547244761 0.500000154724476" type="capsule" />
										<body name="B8" pos="-0.001950903220161282 0.009807852804032305 0.0">
											<joint name="JT8" type="hinge" pos="0.0019134171618254486 -0.004619397662556434 0.0" axis="0 0 1" group="3" damping="1" stiffness="0" limited="true" range="0 0.0872664626" />
											<joint name="JT8_2" type="hinge" pos="0.0019134171618254486 -0.004619397662556434 0.0" axis="0 1 0" group="3" damping="1" stiffness="0" limited="true" range="0 0.0872664626" />
											<joint name="JT8_3" type="hinge" pos="0.0019134171618254486 -0.004619397662556434 0.0" axis="1 0 0" group="3" damping="1" stiffness="0" limited="true" range="0 0.0872664626" />
											<inertial pos="0 0 0" quat="0.3928476007597919 -0.5879379831464158 0.3928476007597919 0.5879379831464158" mass="0.000625" diaginertia="9.41594e-10 9.41594e-10 9.14498e-11" />
											<geom name="G8" size="0.0015 0.005" quat="0.3928476007597919 -0.5879379831464158 0.3928476007597919 0.5879379831464158" type="capsule" />
											<body name="B9" pos="-0.00555570233019602 0.008314696123025454 0.0">
												<joint name="JT9" type="hinge" pos="0.0035355339059327372 -0.003535533905932738 0.0" axis="0 0 1" group="3" damping="1" stiffness="0" limited="true" range="0 0.0872664626" />
												<joint name="JT9_2" type="hinge" pos="0.0035355339059327372 -0.003535533905932738 0.0" axis="0 1 0" group="3" damping="1" stiffness="0" limited="true" range="0 0.0872664626" />
												<joint name="JT9_3" type="hinge" pos="0.0035355339059327372 -0.003535533905932738 0.0" axis="1 0 0" group="3" damping="1" stiffness="0" limited="true" range="0 0.0872664626" />
												<inertial pos="0 0 0" quat="0.2705981338093816 -0.6532816845954584 0.2705981338093816 0.6532816845954584" mass="0.000625" diaginertia="9.41594e-10 9.41594e-10 9.14498e-11" />
												<geom name="G9" size="0.0015 0.005" quat="0.2705981338093816 -0.6532816845954584 0.2705981338093816 0.6532816845954584" type="capsule" />
												<body name="B10" pos="-0.008314696123025454 0.005555702330196022 0.0">
													<joint name="JT10" type="hinge" pos="0.004619397662556434 -0.0019134171618254492 0.0" axis="0 0 1" group="3" damping="1" stiffness="0" limited="true" range="0 0.0872664626" />
													<joint name="JT10_2" type="hinge" pos="0.004619397662556434 -0.0019134171618254492 0.0" axis="0 1 0" group="3" damping="1" stiffness="0" limited="true" range="0 0.0872664626" />
													<joint name="JT10_3" type="hinge" pos="0.004619397662556434 -0.0019134171618254492 0.0" axis="1 0 0" group="3" damping="1" stiffness="0" limited="true" range="0 0.0872664626" />
													<inertial pos="0 0 0" quat="0.13794973232985844 -0.6935201372700871 0.13794973232985844 0.6935201372700871" mass="0.000625" diaginertia="9.41594e-10 9.41594e-10 9.14498e-11" />
													<geom name="G10" size="0.0015 0.005" quat="0.13794973232985844 -0.6935201372700871 0.13794973232985844 0.6935201372700871" type="capsule" />
													<body name="B11" pos="-0.009807852804032305 0.0019509032201612858 0.0">
														<joint name="JT11" type="hinge" pos="0.005 -6.123233995736766e-19 0.0" axis="0 0 1" group="3" damping="1" stiffness="0" limited="true" range="0 0.0872664626" />
														<joint name="JT11_2" type="hinge" pos="0.005 -6.123233995736766e-19 0.0" axis="0 1 0" group="3" damping="1" stiffness="0" limited="true" range="0 0.0872664626" />
														<joint name="JT11_3" type="hinge" pos="0.005 -6.123233995736766e-19 0.0" axis="1 0 0" group="3" damping="1" stiffness="0" limited="true" range="0 0.0872664626" />
														<inertial pos="0 0 0" quat="4.329781621023438e-17 -0.707107 4.329781621023438e-17 0.707107" mass="0.000625" diaginertia="9.41594e-10 9.41594e-10 9.14498e-11" />
														<geom name="G11" size="0.0015 0.005" quat="4.329781621023438e-17 -0.707107 4.329781621023438e-17 0.707107" type="capsule" />
														<body name="B12" pos="-0.009807852804032305 0 0.0">
															<joint name="JT12" type="hinge" pos="0.005 0 0" axis="0 0 1" group="3" damping="1" stiffness="0" limited="true" range="0 0.0872664626" />
															<joint name="JT12_2" type="hinge" pos="0.005 0 0" axis="0 1 0" group="3" damping="1" stiffness="0" limited="true" range="0 0.0872664626" />
															<joint name="JT12_3" type="hinge" pos="0.005 0 0" axis="1 0 0" group="3" damping="1" stiffness="0" limited="true" range="0 0.0872664626" />
															<inertial pos="0 0 0" quat="4.329781621023438e-17 -0.707107 4.329781621023438e-17 0.707107" mass="0.000625" diaginertia="9.41594e-10 9.41594e-10 9.14498e-11" />
															<geom name="G12" size="0.0015 0.005" quat="4.329781621023438e-17 -0.707107 4.329781621023438e-17 0.707107" type="capsule" />
															<body name="B13" pos="-0.009807852804032305 0 0.0">
																<joint name="JT13" type="hinge" pos="0.005 0 0" axis="0 0 1" group="3" damping="1" stiffness="0" limited="true" range="0 0.0872664626" />
																<joint name="JT13_2" type="hinge" pos="0.005 0 0" axis="0 1 0" group="3" damping="1" stiffness="0" limited="true" range="0 0.0872664626" />
																<joint name="JT13_3" type="hinge" pos="0.005 0 0" axis="1 0 0" group="3" damping="1" stiffness="0" limited="true" range="0 0.0872664626" />
																<inertial pos="0 0 0" quat="4.329781621023438e-17 -0.707107 4.329781621023438e-17 0.707107" mass="0.000625" diaginertia="9.41594e-10 9.41594e-10 9.14498e-11" />
																<geom name="G13" size="0.0015 0.005" quat="4.329781621023438e-17 -0.707107 4.329781621023438e-17 0.707107" type="capsule" />
																<body name="B14" pos="-0.009807852804032305 0 0.0">
																	<joint name="JT14" type="hinge" pos="0.005 0 0" axis="0 0 1" group="3" damping="1" stiffness="0" limited="true" range="0 0.0872664626" />
																	<joint name="JT14_2" type="hinge" pos="0.005 0 0" axis="0 1 0" group="3" damping="1" stiffness="0" limited="true" range="0 0.0872664626" />
																	<joint name="JT14_3" type="hinge" pos="0.005 0 0" axis="1 0 0" group="3" damping="1" stiffness="0" limited="true" range="0 0.0872664626" />
																	<inertial pos="0 0 0" quat="4.329781621023438e-17 -0.707107 4.329781621023438e-17 0.707107" mass="0.000625" diaginertia="9.41594e-10 9.41594e-10 9.14498e-11" />
																	<geom name="G14" size="0.0015 0.005" quat="4.329781621023438e-17 -0.707107 4.329781621023438e-17 0.707107" type="capsule" />
																	<body name="B15" pos="-0.009807852804032305 0 0.0">
																		<joint name="JT15" type="hinge" pos="0.005 0 0" axis="0 0 1" group="3" damping="1" stiffness="0" limited="true" range="0 0.0872664626" />
																		<joint name="JT15_2" type="hinge" pos="0.005 0 0" axis="0 1 0" group="3" damping="1" stiffness="0" limited="true" range="0 0.0872664626" />
																		<joint name="JT15_3" type="hinge" pos="0.005 0 0" axis="1 0 0" group="3" damping="1" stiffness="0" limited="true" range="0 0.0872664626" />
																		<inertial pos="0 0 0" quat="4.329781621023438e-17 -0.707107 4.329781621023438e-17 0.707107" mass="0.000625" diaginertia="9.41594e-10 9.41594e-10 9.14498e-11" />
																		<geom name="G15" size="0.0015 0.005" quat="4.329781621023438e-17 -0.707107 4.329781621023438e-17 0.707107" type="capsule" />
																		<body name="B16" pos="-0.009807852804032305 0 0.0">
																			<joint name="JT16" type="hinge" pos="0.005 0 0" axis="0 0 1" group="3" damping="1" stiffness="0" limited="true" range="0 0.0872664626" />
																			<joint name="JT16_2" type="hinge" pos="0.005 0 0" axis="0 1 0" group="3" damping="1" stiffness="0" limited="true" range="0 0.0872664626" />
																			<joint name="JT16_3" type="hinge" pos="0.005 0 0" axis="1 0 0" group="3" damping="1" stiffness="0" limited="true" range="0 0.0872664626" />
																			<inertial pos="0 0 0" quat="4.329781621023438e-17 -0.707107 4.329781621023438e-17 0.707107" mass="0.000625" diaginertia="9.41594e-10 9.41594e-10 9.14498e-11" />
																			<geom name="G16" size="0.0015 0.005" quat="4.329781621023438e-17 -0.707107 4.329781621023438e-17 0.707107" type="capsule" />
																		</body>
																	</body>
																</body>
															</body>
														</body>
													</body>
												</body>
											</body>
										</body>
									</body>
								</body>
							</body>
						</body>
					</body>
				</body>
			</body>
		</body>
				</body>


                <inertial pos="0 0.008561 0.00125" mass="0.088967482" fullinertia="0.00001955483012 0.00000622772374 0.00001955483012 0.000000000 0.000000000 0.000000000" />
                <geom name="qube:motor:main" pos="0 -0.000486 0.00135" type="mesh" contype="0" conaffinity="0" condim="1" friction="0 0 0" material="redMat" mesh="qube0:motor:main" />
                <geom name="qube:motor:drive" pos="0.000009 -0.000053 -0.01472" type="mesh" contype="0" conaffinity="0" condim="1" friction="0 0 0" material="silverMat" mesh="qube0:motor:drive" />
                <geom name="qube:motor:front" pos="0.000031 0.025329 0.00124" type="mesh" contype="0" conaffinity="0" condim="1" friction="0 0 0" material="bodyMat" mesh="qube0:motor:front" />
                <geom name="qube:motor:part" pos="0 0.015289 -0.01559" type="mesh" contype="0" conaffinity="0" condim="1" friction="0 0 0" material="silverMat" mesh="qube0:motor:part" />

                <joint axis="0 0 1" name="base_motor" range="-90 90" type="hinge" damping="3e-04"/>

                <body name="arm" pos="0 0.054882 0">
                    <inertial pos="0 0 0" mass="0.006032518" fullinertia="0.000002500 0.000000030 0.000002500 0.000000000 0.000000000 0.000000000" />
                    <geom name="qube:arm" pos="0 0 0" type="mesh" contype="0" conaffinity="0" condim="1" friction="0 0 0" material="silverMat" mesh="qube0:arm" />

                    <joint axis="0 1 0" name="arm_pole" range="-90 90" type="hinge" damping="3.5e-05"/>

                    <body name="pole" pos="0 0.030562 0">
                        <inertial pos="-0.000022 0 0.05851" mass="0.024" fullinertia="0.000031118 0.000031122 0.000000273 0.000000000 0.000000000 0.000000000" />
                        <geom name="qube:pole" pos="-0.000022 0 0.05851" type="mesh" contype="0" conaffinity="0" condim="1" friction="0 0 0" material="redMat" mesh="qube0:pole" />
                    </body> 
                </body> 

            </body>            
        </body>
    </worldbody>

    <equality>
        <!-- <connect body1="B0" body2="B1" anchor="0.005 0 0" />
        <connect body1="B1" body2="B2" anchor="0.005 0 0" />
        <connect body1="B2" body2="B3" anchor="0.005 0 0" />
        <connect body1="B3" body2="B4" anchor="0.005 0 0" />
        <connect body1="B4" body2="B5" anchor="0.005 0 0" />
        <connect body1="B5" body2="B6" anchor="0.005 0 0" />
        <connect body1="B6" body2="B7" anchor="0.005 0 0" />
        <connect body1="B7" body2="B8" anchor="0.005 0 0" />
        <connect body1="B8" body2="B9" anchor="0.005 0 0" />
        <connect body1="B9" body2="B10" anchor="0.005 0 0" />
        <connect body1="B10" body2="B11" anchor="0.005 0 0" />
        <connect body1="B11" body2="B12" anchor="0.005 0 0" />
        <connect body1="B12" body2="B13" anchor="0.005 0 0" />
        <connect body1="B13" body2="B14" anchor="0.005 0 0" />
        <connect body1="B14" body2="B15" anchor="0.005 0 0" />
        <connect body1="B15" body2="B16" anchor="0.005 0 0" /> -->

        <!-- <joint joint1="JT1" polycoef="0 1 0 0 0" />
        <joint joint1="JT2" polycoef="0 1 0 0 0" />
        <joint joint1="JT3" polycoef="0 1 0 0 0" />
        <joint joint1="JT4" polycoef="0 1 0 0 0" />
        <joint joint1="JT5" polycoef="0 1 0 0 0" />
        <joint joint1="JT6" polycoef="0 1 0 0 0" />
        <joint joint1="JT7" polycoef="0 1 0 0 0" />
        <joint joint1="JT8" polycoef="0 1 0 0 0" />
        <joint joint1="JT9" polycoef="0 1 0 0 0" />
        <joint joint1="JT10" polycoef="0 1 0 0 0" />
        <joint joint1="JT11" polycoef="0 1 0 0 0" />
        <joint joint1="JT12" polycoef="0 1 0 0 0" />
        <joint joint1="JT13" polycoef="0 1 0 0 0" />
        <joint joint1="JT14" polycoef="0 1 0 0 0" />
        <joint joint1="JT15" polycoef="0 1 0 0 0" />
        <joint joint1="JT16" polycoef="0 1 0 0 0" /> -->
        <!-- <weld body1="B0" body2="motor" /> -->
        <weld body1="B15" body2="cable"/>
		<weld body1="cable" body2="base"/>
    </equality>

    <actuator>
        <velocity joint="base_motor" name="motor_rotation" ctrllimited="true" ctrlrange="-18 18" kv="0.0025"/>
        <!-- <motor joint="base_motor" name="motor_rotation" ctrllimited="true" ctrlrange="-18 18"/> -->
    </actuator>
</mujoco>